<?xml version="1.0" encoding="utf-8"?>
<!-- This URDF was automatically created by SolidWorks to URDF Exporter! Originally created by Stephen Brawner (brawner@gmail.com) 
     Commit Version: 1.6.0-4-g7f85cfe  Build Version: 1.6.7995.38578
     For more information, please see http://wiki.ros.org/sw_urdf_exporter -->
<robot
  name="Robotic arm">
  <link
    name="base_link">
    <inertial>
      <origin
        xyz="-0.69679563303847 -0.00816784335744991 0.265731986403883"
        rpy="0 0 0" />
      <mass
        value="0.25317860462902" />
      <inertia
        ixx="0.000828403245741527"
        ixy="3.70541920163951E-05"
        ixz="3.01784146668713E-06"
        iyy="0.000350972792845602"
        iyz="-3.73050861469943E-05"
        izz="0.000828409230624187" />
    </inertial>
    <visual>
      <origin
        xyz="0 0 0"
        rpy="0 0 0" />
      <geometry>
        <mesh
          filename="package://Robotic arm/meshes/base_link.STL" />
      </geometry>
      <material
        name="">
        <color
          rgba="0.792156862745098 0.819607843137255 0.933333333333333 1" />
      </material>
    </visual>
    <collision>
      <origin
        xyz="0 0 0"
        rpy="0 0 0" />
      <geometry>
        <mesh
          filename="package://Robotic arm/meshes/base_link.STL" />
      </geometry>
    </collision>
  </link>
  <link
    name="l1">
    <inertial>
      <origin
        xyz="-2.22044604925031E-16 0.0183275154559336 -0.0312500000000004"
        rpy="0 0 0" />
      <mass
        value="0.00856484506992035" />
      <inertia
        ixx="9.66022619763091E-06"
        ixy="-8.99972506457694E-22"
        ixz="-2.5410988417629E-21"
        iyy="6.60895990111248E-06"
        iyz="-1.20305148289712E-20"
        izz="3.96478275110436E-06" />
    </inertial>
    <visual>
      <origin
        xyz="0 0 0"
        rpy="0 0 0" />
      <geometry>
        <mesh
          filename="package://Robotic arm/meshes/l1.STL" />
      </geometry>
      <material
        name="">
        <color
          rgba="0.894117647058823 0.913725490196078 0.929411764705882 1" />
      </material>
    </visual>
    <collision>
      <origin
        xyz="0 0 0"
        rpy="0 0 0" />
      <geometry>
        <mesh
          filename="package://Robotic arm/meshes/l1.STL" />
      </geometry>
    </collision>
  </link>
  <joint
    name="jt1"
    type="fixed">
    <origin
      xyz="-0.672239905924361 -0.285508163221258 -0.0607021044383488"
      rpy="-1.57867704022667 0.108785793712191 -2.42540916266426" />
    <parent
      link="base_link" />
    <child
      link="l1" />
    <axis
      xyz="0 0 0" />
  </joint>
  <link
    name="l2">
    <inertial>
      <origin
        xyz="-8.88178419700125E-16 -0.0121035978405494 0.0365476590504581"
        rpy="0 0 0" />
      <mass
        value="0.00642116129734904" />
      <inertia
        ixx="1.06416756703803E-06"
        ixy="-9.72764400362361E-22"
        ixz="-1.42936809849163E-21"
        iyy="7.48590411023203E-07"
        iyz="-3.00219563056541E-07"
        izz="9.84127034084534E-07" />
    </inertial>
    <visual>
      <origin
        xyz="0 0 0"
        rpy="0 0 0" />
      <geometry>
        <mesh
          filename="package://Robotic arm/meshes/l2.STL" />
      </geometry>
      <material
        name="">
        <color
          rgba="0.898039215686275 0.917647058823529 0.929411764705882 1" />
      </material>
    </visual>
    <collision>
      <origin
        xyz="0 0 0"
        rpy="0 0 0" />
      <geometry>
        <mesh
          filename="package://Robotic arm/meshes/l2.STL" />
      </geometry>
    </collision>
  </link>
  <joint
    name="joint2"
    type="continuous">
    <origin
      xyz="0 0.0499999999999989 -0.0173803841386614"
      rpy="3.14159265358979 0 0.0406079501401341" />
    <parent
      link="l1" />
    <child
      link="l2" />
    <axis
      xyz="0 0 1" />
  </joint>
  <link
    name="l3">
    <inertial>
      <origin
        xyz="0.00526797315955069 -0.00674231950867726 -5.16253706450698E-14"
        rpy="0 0 0" />
      <mass
        value="0.0299056240871998" />
      <inertia
        ixx="2.44979605081823E-05"
        ixy="1.74541845571235E-06"
        ixz="2.73168125489512E-20"
        iyy="1.6745384090036E-05"
        iyz="1.90582413132218E-20"
        izz="1.2101416361274E-05" />
    </inertial>
    <visual>
      <origin
        xyz="0 0 0"
        rpy="0 0 0" />
      <geometry>
        <mesh
          filename="package://Robotic arm/meshes/l3.STL" />
      </geometry>
      <material
        name="">
        <color
          rgba="0.898039215686275 0.917647058823529 0.929411764705882 1" />
      </material>
    </visual>
    <collision>
      <origin
        xyz="0 0 0"
        rpy="0 0 0" />
      <geometry>
        <mesh
          filename="package://Robotic arm/meshes/l3.STL" />
      </geometry>
    </collision>
  </link>
  <joint
    name="joint3"
    type="fixed">
    <origin
      xyz="0.0104999999999992 -0.0225000000000055 0.0141196158613402"
      rpy="-1.5707963267949 0 -1.5707963267949" />
    <parent
      link="l2" />
    <child
      link="l3" />
    <axis
      xyz="0 0 0" />
  </joint>
  <link
    name="l4">
    <inertial>
      <origin
        xyz="0.000423571393782796 0.0237903672857819 2.01669322925924E-06"
        rpy="0 0 0" />
      <mass
        value="0.0922547988467911" />
      <inertia
        ixx="2.39260289532797E-05"
        ixy="-6.29877046968507E-07"
        ixz="-3.25333691981167E-09"
        iyy="3.92472604810845E-05"
        iyz="-1.21334747488215E-09"
        izz="4.97573758155457E-05" />
    </inertial>
    <visual>
      <origin
        xyz="0 0 0"
        rpy="0 0 0" />
      <geometry>
        <mesh
          filename="package://Robotic arm/meshes/l4.STL" />
      </geometry>
      <material
        name="">
        <color
          rgba="0.792156862745098 0.819607843137255 0.933333333333333 1" />
      </material>
    </visual>
    <collision>
      <origin
        xyz="0 0 0"
        rpy="0 0 0" />
      <geometry>
        <mesh
          filename="package://Robotic arm/meshes/l4.STL" />
      </geometry>
    </collision>
  </link>
  <joint
    name="motor"
    type="fixed">
    <origin
      xyz="0.0163442401711011 -0.0266508074623717 0.000642634023008903"
      rpy="0 1.55334303434829 0" />
    <parent
      link="l3" />
    <child
      link="l4" />
    <axis
      xyz="0 0 0" />
  </joint>
  <link
    name="l5">
    <inertial>
      <origin
        xyz="3.03923552991137E-14 -0.0142942180766732 8.88178419700125E-15"
        rpy="0 0 0" />
      <mass
        value="0.00180689470752886" />
      <inertia
        ixx="4.36643567346642E-08"
        ixy="4.69683491565266E-23"
        ixz="1.4475660719678E-24"
        iyy="8.22625639685291E-08"
        iyz="2.81241408268029E-23"
        izz="4.36643567346642E-08" />
    </inertial>
    <visual>
      <origin
        xyz="0 0 0"
        rpy="0 0 0" />
      <geometry>
        <mesh
          filename="package://Robotic arm/meshes/l5.STL" />
      </geometry>
      <material
        name="">
        <color
          rgba="0.666666666666667 0.698039215686274 0.768627450980392 1" />
      </material>
    </visual>
    <collision>
      <origin
        xyz="0 0 0"
        rpy="0 0 0" />
      <geometry>
        <mesh
          filename="package://Robotic arm/meshes/l5.STL" />
      </geometry>
    </collision>
  </link>
  <joint
    name="motor shaft"
    type="continuous">
    <origin
      xyz="0.019499999999959 0.0402007200296159 0"
      rpy="-3.14159265358979 1.40973719906846 0" />
    <parent
      link="l4" />
    <child
      link="l5" />
    <axis
      xyz="0 1 0" />
  </joint>
  <link
    name="l6">
    <inertial>
      <origin
        xyz="-8.32667268468867E-17 0.0183275154559351 -0.0312500000000002"
        rpy="0 0 0" />
      <mass
        value="0.00856484506992047" />
      <inertia
        ixx="9.66022619763108E-06"
        ixy="-2.0216294170796E-21"
        ixz="-1.5613861242551E-20"
        iyy="6.60895990111256E-06"
        iyz="1.6940658945086E-20"
        izz="3.96478275110445E-06" />
    </inertial>
    <visual>
      <origin
        xyz="0 0 0"
        rpy="0 0 0" />
      <geometry>
        <mesh
          filename="package://Robotic arm/meshes/l6.STL" />
      </geometry>
      <material
        name="">
        <color
          rgba="0.894117647058823 0.913725490196078 0.929411764705882 1" />
      </material>
    </visual>
    <collision>
      <origin
        xyz="0 0 0"
        rpy="0 0 0" />
      <geometry>
        <mesh
          filename="package://Robotic arm/meshes/l6.STL" />
      </geometry>
    </collision>
  </link>
  <joint
    name="joint6"
    type="fixed">
    <origin
      xyz="0 -0.0179500874327593 -0.0499999999999989"
      rpy="1.5707963267949 0 0" />
    <parent
      link="l5" />
    <child
      link="l6" />
    <axis
      xyz="0 0 0" />
  </joint>
  <link
    name="l7">
    <inertial>
      <origin
        xyz="-0.0312499999999994 0.000634844610749294 -0.454886154222958"
        rpy="0 0 0" />
      <mass
        value="1.26362254671649" />
      <inertia
        ixx="0.102670063848464"
        ixy="-4.33680868994202E-18"
        ixz="1.53468817515323E-16"
        iyy="0.102669902721398"
        iyz="-5.75964646934286E-08"
        izz="0.00186883040185773" />
    </inertial>
    <visual>
      <origin
        xyz="0 0 0"
        rpy="0 0 0" />
      <geometry>
        <mesh
          filename="package://Robotic arm/meshes/l7.STL" />
      </geometry>
      <material
        name="">
        <color
          rgba="0.643137254901961 0.615686274509804 0.6 1" />
      </material>
    </visual>
    <collision>
      <origin
        xyz="0 0 0"
        rpy="0 0 0" />
      <geometry>
        <mesh
          filename="package://Robotic arm/meshes/l7.STL" />
      </geometry>
    </collision>
  </link>
  <joint
    name="bigarm"
    type="continuous">
    <origin
      xyz="0 0.0099999999999999 0"
      rpy="1.68565517922975 -1.5707963267949 0" />
    <parent
      link="l6" />
    <child
      link="l7" />
    <axis
      xyz="1 0 0" />
  </joint>
</robot>